Workbook
Name _020Spread_TRH_A: [1]PARAM!$B$2
Name ddddddddddd: #REF!
Name ddddddddddd: #REF!
Name ddddddddddd: #REF!
Name ddddddddddd: #REF!
Name ddddddddddd: #REF!
Name ddddddddddd: #REF!
Name ddddddddddd: #REF!
Name ddddddddddd: #REF!
Name ddddddddddd: #REF!
Name ddddddddddd: #REF!
Name ddddddddddd: #REF!
Name ddddddddddd: #REF!
Name ddddddddddd: #REF!
Name ddddddddddd: #REF!
Name ddddddddddd: #REF!
Name ddddddddddd: #REF!
Name ddddddddddd: #REF!
Name ddddddddddd: #REF!
Name ddddddddddd: #REF!
Name ddddddddddd: #REF!
Name ddddddddddd: #REF!
Name NTopProcesses: #REF!
Name NTopProcesses: #REF!
Name NTopProcesses: #REF!
Name NTopProcesses: #REF!
Name NTopProcesses: #REF!
Name NTopProcesses: #REF!
Name NTopProcesses: #REF!
Name NTopProcesses: #REF!
Name NTopProcesses: #REF!
Name NTopProcesses: #REF!
Name NTopProcesses: #REF!
Name NTopProcesses: #REF!
Name NTopProcesses: #REF!
Name NTopProcesses: #REF!
Name NTopProcesses: #REF!
Name NTopProcesses: #REF!
Name NTopProcesses: #REF!
Name NTopProcesses: #REF!
Name Process_Weight_Difference_Factor: #REF!
Name Process_Weight_Difference_Factor: #REF!
Name Process_Weight_Difference_Factor: #REF!
Name Process_Weight_Difference_Factor: #REF!
Name Process_Weight_Difference_Factor: #REF!
Name Process_Weight_Difference_Factor: #REF!
Name Process_Weight_Difference_Factor: #REF!
Name Process_Weight_Difference_Factor: #REF!
Name Process_Weight_Difference_Factor: #REF!
Name Process_Weight_Difference_Factor: #REF!
Name Process_Weight_Difference_Factor: #REF!
Name Process_Weight_Difference_Factor: #REF!
Name Process_Weight_Difference_Factor: #REF!
Name Process_Weight_Difference_Factor: #REF!
Name Process_Weight_Difference_Factor: #REF!
Name Process_Weight_Difference_Factor: #REF!
Name Process_Weight_Difference_Factor: #REF!
Name Process_Weight_Difference_Factor: #REF!
Name Process_Weight_Difference_Factor: #REF!
Name Process_Weight_Difference_Factor: #REF!

Sheet Instructions
A1: COBIT® 2019 Governance System Design Workbook—Instructions
A3: Terms & Definitions
B5: Relative importance | C5: Relative importance (of governance and management objectives) is a number that indicates the influence of a certain design factor on the importance of a certain COBIT governance or management objective as compared to a baseline (standard) situation. The number is calculated as a percentage difference between the baseline and the current situation, as determined by the values given to the design factor at hand.
A7: Instructions: See COBIT® 2019 Design Guide, Chapter 6

Sheet Canvas
A1: COBIT® 2019 Governance System Design Workbook—Canvas
B3: Step 2: Determine the initial scope of the Governance System | I3: Step 3: Refine the scope of the Governance System | S3: Step 4: Conclude the Scope of the Governance System
A4: Design Factors: | B4: Enterprise Strategy | C4: Enterprise Goals | D4: Risk Profile | E4: I&T-Related Issues | G4: Initial Scope: Governance/ Management Objectives Score | I4: Threat Landscape | J4: Compliance Req's | K4: Role of IT | L4: Sourcing Model for IT | M4: IT Implementation Methods | N4: Technology Adoption Strategy | O4: Size | Q4: Refined Scope: Governance/ Management Objectives Score | S4: Adjustment (between -100 and +100) | T4: Reason | U4: Concluded Scope: Governance/ Management Objectives Priority | W4: Suggested Target Capability Level | X4: Agreed Target Capability Level | Y4: Reason
A5: Weight | B5: 1 | C5: 1 | D5: 1 | E5: 1 | I5: 1 | J5: 1 | K5: 1 | L5: 1 | M5: 1 | N5: 1 | O5: 0
A6: EDM01—Ensured Governance Framework Setting & Maintenance | B6: ='DF1'!D22 -> 5 | C6: ='DF2'!D31 -> -10 | D6: ='DF3'!D35 -> -15 | E6: ='DF4'!D31 -> 0 | F6: =SUMPRODUCT(B$5:E$5,B6:E6) -> -20 | G6: =IFERROR(IF(F6>=0,MROUND(TRUNC(100*SUMPRODUCT(B$5:E$5,B6:E6)/MAX(F$50:F$51)),5),MROUND(TRUNC(100*SUMPRODUCT(B$5:E$5,B6:E6)/MAX(F$50:F$51)),-5)),0) -> -20 | I6: ='DF5'!D30 -> -30 | J6: ='DF6'!D30 -> 40 | K6: ='DF7'!D32 -> -25 | L6: ='DF8'!D32 -> 0 | M6: ='DF9'!D28 -> 0 | N6: ='DF10'!D22 -> 0 | O6: 0 | P6: =SUMPRODUCT(B$5:E$5,B6:E6)+SUMPRODUCT(I$5:N$5,I6:N6) -> -35 | Q6: =IFERROR(IF(P6>0,MROUND(TRUNC(100*SUMPRODUCT(B$5:N$5,B6:N6)/MAX(P$50:P$51)),5),MROUND(TRUNC(100*SUMPRODUCT(B$5:N$5,B6:N6)/MAX(P$50:P$51)),-5)),0) -> -30 | U6: =Q6+S6 -> -30 | W6: =IF(U6>=75,4,IF(U6>=50,3,IF(U6>=25,2,1))) -> 1 | X6: =W6 -> 1
A7: EDM02—Ensured Benefits Delivery | B7: ='DF1'!D23 -> 20 | C7: ='DF2'!D32 -> -25 | D7: ='DF3'!D36 -> 5 | E7: ='DF4'!D32 -> -5 | F7: =SUMPRODUCT(B$5:E$5,B7:E7) -> -5 | G7: =IFERROR(IF(F7>=0,MROUND(TRUNC(100*SUMPRODUCT(B$5:E$5,B7:E7)/MAX(F$50:F$51)),5),MROUND(TRUNC(100*SUMPRODUCT(B$5:E$5,B7:E7)/MAX(F$50:F$51)),-5)),0) -> -5 | I7: ='DF5'!D31 -> 0 | J7: ='DF6'!D31 -> 0 | K7: ='DF7'!D33 -> -25 | L7: ='DF8'!D33 -> 0 | M7: ='DF9'!D29 -> 0 | N7: ='DF10'!D23 -> 0 | O7: 0 | P7: =SUMPRODUCT(B$5:E$5,B7:E7)+SUMPRODUCT(I$5:N$5,I7:N7) -> -30 | Q7: =IFERROR(IF(P7>0,MROUND(TRUNC(100*SUMPRODUCT(B$5:N$5,B7:N7)/MAX(P$50:P$51)),5),MROUND(TRUNC(100*SUMPRODUCT(B$5:N$5,B7:N7)/MAX(P$50:P$51)),-5)),0) -> -25 | U7: =Q7+S7 -> -25 | W7: =IF(U7>=75,4,IF(U7>=50,3,IF(U7>=25,2,1))) -> 1 | X7: =W7 -> 1
A8: EDM03—Ensured Risk Optimization | B8: ='DF1'!D24 -> 15 | C8: ='DF2'!D33 -> 20 | D8: ='DF3'!D37 -> 5 | E8: ='DF4'!D33 -> 5 | F8: =SUMPRODUCT(B$5:E$5,B8:E8) -> 45 | G8: =IFERROR(IF(F8>=0,MROUND(TRUNC(100*SUMPRODUCT(B$5:E$5,B8:E8)/MAX(F$50:F$51)),5),MROUND(TRUNC(100*SUMPRODUCT(B$5:E$5,B8:E8)/MAX(F$50:F$51)),-5)),0) -> 45 | I8: ='DF5'!D32 -> -35 | J8: ='DF6'!D32 -> 80 | K8: ='DF7'!D34 -> -25 | L8: ='DF8'!D34 -> -15 | M8: ='DF9'!D30 -> 0 | N8: ='DF10'!D24 -> 0 | O8: 0 | P8: =SUMPRODUCT(B$5:E$5,B8:E8)+SUMPRODUCT(I$5:N$5,I8:N8) -> 50 | Q8: =IFERROR(IF(P8>0,MROUND(TRUNC(100*SUMPRODUCT(B$5:N$5,B8:N8)/MAX(P$50:P$51)),5),MROUND(TRUNC(100*SUMPRODUCT(B$5:N$5,B8:N8)/MAX(P$50:P$51)),-5)),0) -> 40 | U8: =Q8+S8 -> 40 | W8: =IF(U8>=75,4,IF(U8>=50,3,IF(U8>=25,2,1))) -> 2 | X8: =W8 -> 2
A9: EDM04—Ensured Resource Optimization | B9: ='DF1'!D25 -> 0 | C9: ='DF2'!D34 -> -25 | D9: ='DF3'!D38 -> -15 | E9: ='DF4'!D34 -> -5 | F9: =SUMPRODUCT(B$5:E$5,B9:E9) -> -45 | G9: =IFERROR(IF(F9>=0,MROUND(TRUNC(100*SUMPRODUCT(B$5:E$5,B9:E9)/MAX(F$50:F$51)),5),MROUND(TRUNC(100*SUMPRODUCT(B$5:E$5,B9:E9)/MAX(F$50:F$51)),-5)),0) -> -45 | I9: ='DF5'!D33 -> 0 | J9: ='DF6'!D33 -> 0 | K9: ='DF7'!D35 -> -10 | L9: ='DF8'!D35 -> 0 | M9: ='DF9'!D31 -> 0 | N9: ='DF10'!D25 -> 0 | O9: 0 | P9: =SUMPRODUCT(B$5:E$5,B9:E9)+SUMPRODUCT(I$5:N$5,I9:N9) -> -55 | Q9: =IFERROR(IF(P9>0,MROUND(TRUNC(100*SUMPRODUCT(B$5:N$5,B9:N9)/MAX(P$50:P$51)),5),MROUND(TRUNC(100*SUMPRODUCT(B$5:N$5,B9:N9)/MAX(P$50:P$51)),-5)),0) -> -45 | U9: =Q9+S9 -> -45 | W9: =IF(U9>=75,4,IF(U9>=50,3,IF(U9>=25,2,1))) -> 1 | X9: =W9 -> 1
A10: EDM05—Ensured Stakeholder Engagement | B10: ='DF1'!D26 -> 5 | C10: ='DF2'!D35 -> 15 | D10: ='DF3'!D39 -> -20 | E10: ='DF4'!D35 -> -5 | F10: =SUMPRODUCT(B$5:E$5,B10:E10) -> -5 | G10: =IFERROR(IF(F10>=0,MROUND(TRUNC(100*SUMPRODUCT(B$5:E$5,B10:E10)/MAX(F$50:F$51)),5),MROUND(TRUNC(100*SUMPRODUCT(B$5:E$5,B10:E10)/MAX(F$50:F$51)),-5)),0) -> -5 | I10: ='DF5'!D34 -> -15 | J10: ='DF6'!D34 -> 40 | K10: ='DF7'!D36 -> -10 | L10: ='DF8'!D36 -> 0 | M10: ='DF9'!D32 -> 0 | N10: ='DF10'!D26 -> 0 | O10: 0 | P10: =SUMPRODUCT(B$5:E$5,B10:E10)+SUMPRODUCT(I$5:N$5,I10:N10) -> 10 | Q10: =IFERROR(IF(P10>0,MROUND(TRUNC(100*SUMPRODUCT(B$5:N$5,B10:N10)/MAX(P$50:P$51)),5),MROUND(TRUNC(100*SUMPRODUCT(B$5:N$5,B10:N10)/MAX(P$50:P$51)),-5)),0) -> 10 | U10: =Q10+S10 -> 10 | W10: =IF(U10>=75,4,IF(U10>=50,3,IF(U10>=25,2,1))) -> 1 | X10: =W10 -> 1
A11: APO01—Managed I&T Management Framework | B11: ='DF1'!D27 -> 0 | C11: ='DF2'!D36 -> -5 | D11: ='DF3'!D40 -> 10 | E11: ='DF4'!D36 -> 0 | F11: =SUMPRODUCT(B$5:E$5,B11:E11) -> 5 | G11: =IFERROR(IF(F11>=0,MROUND(TRUNC(100*SUMPRODUCT(B$5:E$5,B11:E11)/MAX(F$50:F$51)),5),MROUND(TRUNC(100*SUMPRODUCT(B$5:E$5,B11:E11)/MAX(F$50:F$51)),-5)),0) -> 5 | I11: ='DF5'!D35 -> -30 | J11: ='DF6'!D35 -> 25 | K11: ='DF7'!D37 -> -20 | L11: ='DF8'!D37 -> 0 | M11: ='DF9'!D33 -> 0 | N11: ='DF10'!D27 -> 0 | O11: 0 | P11: =SUMPRODUCT(B$5:E$5,B11:E11)+SUMPRODUCT(I$5:N$5,I11:N11) -> -20 | Q11: =IFERROR(IF(P11>0,MROUND(TRUNC(100*SUMPRODUCT(B$5:N$5,B11:N11)/MAX(P$50:P$51)),5),MROUND(TRUNC(100*SUMPRODUCT(B$5:N$5,B11:N11)/MAX(P$50:P$51)),-5)),0) -> -15 | U11: =Q11+S11 -> -15 | W11: =IF(U11>=75,4,IF(U11>=50,3,IF(U11>=25,2,1))) -> 1 | X11: =W11 -> 1
A12: APO02—Managed Strategy | B12: ='DF1'!D28 -> -20 | C12: ='DF2'!D37 -> -25 | D12: ='DF3'!D41 -> -5 | E12: ='DF4'!D37 -> -5 | F12: =SUMPRODUCT(B$5:E$5,B12:E12) -> -55 | G12: =IFERROR(IF(F12>=0,MROUND(TRUNC(100*SUMPRODUCT(B$5:E$5,B12:E12)/MAX(F$50:F$51)),5),MROUND(TRUNC(100*SUMPRODUCT(B$5:E$5,B12:E12)/MAX(F$50:F$51)),-5)),0) -> -55 | I12: ='DF5'!D36 -> 0 | J12: ='DF6'!D36 -> 0 | K12: ='DF7'!D38 -> -25 | L12: ='DF8'!D38 -> 0 | M12: ='DF9'!D34 -> 0 | N12: ='DF10'!D28 -> 0 | O12: 0 | P12: =SUMPRODUCT(B$5:E$5,B12:E12)+SUMPRODUCT(I$5:N$5,I12:N12) -> -80 | Q12: =IFERROR(IF(P12>0,MROUND(TRUNC(100*SUMPRODUCT(B$5:N$5,B12:N12)/MAX(P$50:P$51)),5),MROUND(TRUNC(100*SUMPRODUCT(B$5:N$5,B12:N12)/MAX(P$50:P$51)),-5)),0) -> -65 | U12: =Q12+S12 -> -65 | W12: =IF(U12>=75,4,IF(U12>=50,3,IF(U12>=25,2,1))) -> 1 | X12: =W12 -> 1
A13: APO03—Managed Enterprise Architecture | B13: ='DF1'!D29 -> -15 | C13: ='DF2'!D38 -> -20 | D13: ='DF3'!D42 -> 20 | E13: ='DF4'!D38 -> 5 | F13: =SUMPRODUCT(B$5:E$5,B13:E13) -> -10 | G13: =IFERROR(IF(F13>=0,MROUND(TRUNC(100*SUMPRODUCT(B$5:E$5,B13:E13)/MAX(F$50:F$51)),5),MROUND(TRUNC(100*SUMPRODUCT(B$5:E$5,B13:E13)/MAX(F$50:F$51)),-5)),0) -> -10 | I13: ='DF5'!D37 -> -30 | J13: ='DF6'!D37 -> 0 | K13: ='DF7'!D39 -> -15 | L13: ='DF8'!D39 -> 0 | M13: ='DF9'!D35 -> 0 | N13: ='DF10'!D29 -> -5 | O13: 0 | P13: =SUMPRODUCT(B$5:E$5,B13:E13)+SUMPRODUCT(I$5:N$5,I13:N13) -> -60 | Q13: =IFERROR(IF(P13>0,MROUND(TRUNC(100*SUMPRODUCT(B$5:N$5,B13:N13)/MAX(P$50:P$51)),5),MROUND(TRUNC(100*SUMPRODUCT(B$5:N$5,B13:N13)/MAX(P$50:P$51)),-5)),0) -> -50 | U13: =Q13+S13 -> -50 | W13: =IF(U13>=75,4,IF(U13>=50,3,IF(U13>=25,2,1))) -> 1 | X13: =W13 -> 1
A14: APO04—Managed Innovation | B14: ='DF1'!D30 -> -15 | C14: ='DF2'!D39 -> -30 | D14: ='DF3'!D43 -> -20 | E14: ='DF4'!D39 -> -10 | F14: =SUMPRODUCT(B$5:E$5,B14:E14) -> -75 | G14: =IFERROR(IF(F14>=0,MROUND(TRUNC(100*SUMPRODUCT(B$5:E$5,B14:E14)/MAX(F$50:F$51)),5),MROUND(TRUNC(100*SUMPRODUCT(B$5:E$5,B14:E14)/MAX(F$50:F$51)),-5)),0) -> -75 | I14: ='DF5'!D38 -> 0 | J14: ='DF6'!D38 -> 0 | K14: ='DF7'!D40 -> -40 | L14: ='DF8'!D40 -> 0 | M14: ='DF9'!D36 -> 0 | N14: ='DF10'!D30 -> 0 | O14: 0 | P14: =SUMPRODUCT(B$5:E$5,B14:E14)+SUMPRODUCT(I$5:N$5,I14:N14) -> -115 | Q14: =IFERROR(IF(P14>0,MROUND(TRUNC(100*SUMPRODUCT(B$5:N$5,B14:N14)/MAX(P$50:P$51)),5),MROUND(TRUNC(100*SUMPRODUCT(B$5:N$5,B14:N14)/MAX(P$50:P$51)),-5)),0) -> -90 | U14: =Q14+S14 -> -90 | W14: =IF(U14>=75,4,IF(U14>=50,3,IF(U14>=25,2,1))) -> 1 | X14: =W14 -> 1
A15: APO05—Managed Portfolio | B15: ='DF1'!D31 -> -15 | C15: ='DF2'!D40 -> -25 | D15: ='DF3'!D44 -> -10 | E15: ='DF4'!D40 -> 0 | F15: =SUMPRODUCT(B$5:E$5,B15:E15) -> -50 | G15: =IFERROR(IF(F15>=0,MROUND(TRUNC(100*SUMPRODUCT(B$5:E$5,B15:E15)/MAX(F$50:F$51)),5),MROUND(TRUNC(100*SUMPRODUCT(B$5:E$5,B15:E15)/MAX(F$50:F$51)),-5)),0) -> -50 | I15: ='DF5'!D39 -> 0 | J15: ='DF6'!D39 -> 0 | K15: ='DF7'!D41 -> -25 | L15: ='DF8'!D41 -> 0 | M15: ='DF9'!D37 -> 0 | N15: ='DF10'!D31 -> 0 | O15: 0 | P15: =SUMPRODUCT(B$5:E$5,B15:E15)+SUMPRODUCT(I$5:N$5,I15:N15) -> -75 | Q15: =IFERROR(IF(P15>0,MROUND(TRUNC(100*SUMPRODUCT(B$5:N$5,B15:N15)/MAX(P$50:P$51)),5),MROUND(TRUNC(100*SUMPRODUCT(B$5:N$5,B15:N15)/MAX(P$50:P$51)),-5)),0) -> -60 | U15: =Q15+S15 -> -60 | W15: =IF(U15>=75,4,IF(U15>=50,3,IF(U15>=25,2,1))) -> 1 | X15: =W15 -> 1
A16: APO06—Managed Budget & Costs | B16: ='DF1'!D32 -> 0 | C16: ='DF2'!D41 -> -5 | D16: ='DF3'!D45 -> -40 | E16: ='DF4'!D41 -> 0 | F16: =SUMPRODUCT(B$5:E$5,B16:E16) -> -45 | G16: =IFERROR(IF(F16>=0,MROUND(TRUNC(100*SUMPRODUCT(B$5:E$5,B16:E16)/MAX(F$50:F$51)),5),MROUND(TRUNC(100*SUMPRODUCT(B$5:E$5,B16:E16)/MAX(F$50:F$51)),-5)),0) -> -45 | I16: ='DF5'!D40 -> 0 | J16: ='DF6'!D40 -> 0 | K16: ='DF7'!D42 -> -10 | L16: ='DF8'!D42 -> 0 | M16: ='DF9'!D38 -> 0 | N16: ='DF10'!D32 -> 5 | O16: 0 | P16: =SUMPRODUCT(B$5:E$5,B16:E16)+SUMPRODUCT(I$5:N$5,I16:N16) -> -50 | Q16: =IFERROR(IF(P16>0,MROUND(TRUNC(100*SUMPRODUCT(B$5:N$5,B16:N16)/MAX(P$50:P$51)),5),MROUND(TRUNC(100*SUMPRODUCT(B$5:N$5,B16:N16)/MAX(P$50:P$51)),-5)),0) -> -40 | U16: =Q16+S16 -> -40 | W16: =IF(U16>=75,4,IF(U16>=50,3,IF(U16>=25,2,1))) -> 1 | X16: =W16 -> 1
A17: APO07—Managed Human Resources | B17: ='DF1'!D33 -> -5 | C17: ='DF2'!D42 -> -20 | D17: ='DF3'!D46 -> 0 | E17: ='DF4'!D42 -> 5 | F17: =SUMPRODUCT(B$5:E$5,B17:E17) -> -20 | G17: =IFERROR(IF(F17>=0,MROUND(TRUNC(100*SUMPRODUCT(B$5:E$5,B17:E17)/MAX(F$50:F$51)),5),MROUND(TRUNC(100*SUMPRODUCT(B$5:E$5,B17:E17)/MAX(F$50:F$51)),-5)),0) -> -20 | I17: ='DF5'!D41 -> -15 | J17: ='DF6'!D41 -> 0 | K17: ='DF7'!D43 -> -5 | L17: ='DF8'!D43 -> 0 | M17: ='DF9'!D39 -> 0 | N17: ='DF10'!D33 -> -5 | O17: 0 | P17: =SUMPRODUCT(B$5:E$5,B17:E17)+SUMPRODUCT(I$5:N$5,I17:N17) -> -45 | Q17: =IFERROR(IF(P17>0,MROUND(TRUNC(100*SUMPRODUCT(B$5:N$5,B17:N17)/MAX(P$50:P$51)),5),MROUND(TRUNC(100*SUMPRODUCT(B$5:N$5,B17:N17)/MAX(P$50:P$51)),-5)),0) -> -35 | U17: =Q17+S17 -> -35 | W17: =IF(U17>=75,4,IF(U17>=50,3,IF(U17>=25,2,1))) -> 1 | X17: =W17 -> 1
... A45: MEA04—Managed Assurance | B45: ='DF1'!D61 -> 0 | C45: ='DF2'!D70 -> 10 | D45: ='DF3'!D74 -> 5 | E45: ='DF4'!D70 -> 0 | F45: =SUMPRODUCT(B$5:E$5,B45:E45) -> 15 | G45: =IFERROR(IF(F45>=0,MROUND(TRUNC(100*SUMPRODUCT(B$5:E$5,B45:E45)/MAX(F$50:F$51)),5),MROUND(TRUNC(100*SUMPRODUCT(B$5:E$5,B45:E45)/MAX(F$50:F$51)),-5)),0) -> 15 | I45: ='DF5'!D69 -> -30 | J45: ='DF6'!D69 -> 60 | K45: ='DF7'!D71 -> -10 | L45: ='DF8'!D71 -> 0 | M45: ='DF9'!D67 -> 0 | N45: ='DF10'!D61 -> 0 | O45: 0 | P45: =SUMPRODUCT(B$5:E$5,B45:E45)+SUMPRODUCT(I$5:N$5,I45:N45) -> 35 | Q45: =IFERROR(IF(P45>0,MROUND(TRUNC(100*SUMPRODUCT(B$5:N$5,B45:N45)/MAX(P$50:P$51)),5),MROUND(TRUNC(100*SUMPRODUCT(B$5:N$5,B45:N45)/MAX(P$50:P$51)),-5)),0) -> 30 | U45: =Q45+S45 -> 30 | W45: =IF(U45>=75,4,IF(U45>=50,3,IF(U45>=25,2,1))) -> 2 | X45: =W45 -> 2
B47: =AVERAGE(B6:B45) -> 4 | C47: =AVERAGE(C6:C45) -> -10.125 | D47: =AVERAGE(D6:D45) -> 17.75 | E47: =AVERAGE(E6:E45) -> 3.625 | G47: =AVERAGE(G6:G45) -> 15.25 | I47: =AVERAGE(I6:I45) -> -15.875 | J47: =AVERAGE(J6:J45) -> 15.75 | K47: =AVERAGE(K6:K45) -> -18.5 | L47: =AVERAGE(L6:L45) -> -3.375 | M47: =AVERAGE(M6:M45) -> 9.25 | N47: =AVERAGE(N6:N45) -> -0.25 | Q47: =AVERAGE(Q6:Q45) -> 1.625
F50: =MAX(F6:F45) -> 100 | P50: =MAX(P6:P45) -> 125
F51: =-MIN(F6:F45) -> 75 | P51: =-MIN(P6:P45) -> 115

Sheet DF1
A1: Information & Technology Governance System Design Design Factor 1 Enterprise Strategy | J1: Information & Technology Governance System Design Design Factor 1 Enterprise Strategy
A3: Input Section—Importance of Each Enterprise Strategy Archetype | J3: Input Section—Importance of Each Enterprise Strategy Archetype
A6: Value | D6: Importance (1-5) | E6: Baseline
A7: Growth/Acquisition | D7: 2 | E7: 3
A8: Innovation/Differentiation | D8: 2 | E8: 3
A9: Cost Leadership | D9: 3 | E9: 3
A10: Client Service/Stability | D10: 5 | E10: 3
C12: Average | E12: =AVERAGE(D7:D10) -> 3
C13: Stdev | E13: =STDEVP(D7:D10) -> 1.2247449
C14: Correction Factor | E14: =AVERAGE(E7:E10)/E12 -> 1
A18: Output Section—Resulting relative importance of each governance/management objective | J18: Output Section—Resulting relative importance of each governance/management objective
A20: Resulting Governance/Management Objectives Importance
A21: Governance / Management Objective | B21: Score | C21: Baseline Score | D21: Relative Importance
A22: =LEFT(Canvas!A6,5) -> EDM01 | B22: {=MMULT(DF1map!B2:E41,'DF1'!D7:D10)} -> 16 | C22: {=MMULT(DF1map!B2:E41,'DF1'!E7:E10)} -> 15 | D22: =IFERROR(MROUND($E$14*100*B22/C22,5)-100,0) -> 5
A23: =LEFT(Canvas!A7,5) -> EDM02 | B23: 28.5 | C23: 24 | D23: =IFERROR(MROUND($E$14*100*B23/C23,5)-100,0) -> 20
A24: =LEFT(Canvas!A8,5) -> EDM03 | B24: 17 | C24: 15 | D24: =IFERROR(MROUND($E$14*100*B24/C24,5)-100,0) -> 15
A25: =LEFT(Canvas!A9,5) -> EDM04 | B25: 22 | C25: 22.5 | D25: =IFERROR(MROUND($E$14*100*B25/C25,5)-100,0) -> 0
A26: =LEFT(Canvas!A10,5) -> EDM05 | B26: 19 | C26: 18 | D26: =IFERROR(MROUND($E$14*100*B26/C26,5)-100,0) -> 5
A27: =LEFT(Canvas!A11,5) -> APO01 | B27: 12 | C27: 12 | D27: =IFERROR(MROUND($E$14*100*B27/C27,5)-100,0) -> 0
A28: =LEFT(Canvas!A12,5) -> APO02 | B28: 23.5 | C28: 28.5 | D28: =IFERROR(MROUND($E$14*100*B28/C28,5)-100,0) -> -20
A29: =LEFT(Canvas!A13,5) -> APO03 | B29: 20 | C29: 24 | D29: =IFERROR(MROUND($E$14*100*B29/C29,5)-100,0) -> -15
A30: =LEFT(Canvas!A14,5) -> APO04 | B30: 18 | C30: 21 | D30: =IFERROR(MROUND($E$14*100*B30/C30,5)-100,0) -> -15
A31: =LEFT(Canvas!A15,5) -> APO05 | B31: 27.5 | C31: 33 | D31: =IFERROR(MROUND($E$14*100*B31/C31,5)-100,0) -> -15
A32: =LEFT(Canvas!A16,5) -> APO06 | B32: 22 | C32: 22.5 | D32: =IFERROR(MROUND($E$14*100*B32/C32,5)-100,0) -> 0
A33: =LEFT(Canvas!A17,5) -> APO07 | B33: 14 | C33: 15 | D33: =IFERROR(MROUND($E$14*100*B33/C33,5)-100,0) -> -5
A34: =LEFT(Canvas!A18,5) -> APO08 | B34: 25.5 | C34: 21 | D34: =IFERROR(MROUND($E$14*100*B34/C34,5)-100,0) -> 20
... A61: =LEFT(Canvas!A45,5) -> MEA04 | B61: 12 | C61: 12 | D61: =IFERROR(MROUND($E$14*100*B61/C61,5)-100,0) -> 0

Sheet DF1map
A1: DF1 | B1: Growth / Acquisition | C1: Innovation / Differentiation | D1: Cost Leadership | E1: Client Service / Stability
A2: EDM01 | B2: 1 | C2: 1 | D2: 1.5 | E2: 1.5
A3: EDM02 | B3: 1.5 | C3: 1 | D3: 2 | E3: 3.5
A4: EDM03 | B4: 1 | C4: 1 | D4: 1 | E4: 2
A5: EDM04 | B5: 1.5 | C5: 1 | D5: 4 | E5: 1
A6: EDM05 | B6: 1.5 | C6: 1.5 | D6: 1 | E6: 2
A7: APO01 | B7: 1 | C7: 1 | D7: 1 | E7: 1
A8: APO02 | B8: 3.5 | C8: 3.5 | D8: 1.5 | E8: 1
A9: APO03 | B9: 4 | C9: 2 | D9: 1 | E9: 1
A10: APO04 | B10: 1 | C10: 4 | D10: 1 | E10: 1
A11: APO05 | B11: 3.5 | C11: 4 | D11: 2.5 | E11: 1
A12: APO06 | B12: 1.5 | C12: 1 | D12: 4 | E12: 1
A13: APO07 | B13: 2 | C13: 1 | D13: 1 | E13: 1
... A41: MEA04 | B41: 1 | C41: 1 | D41: 1 | E41: 1

Sheet DF2
A1: Information & Technology Governance System Design Design Factor 2 Enterprise Goals | I1: Information & Technology Governance System Design Design Factor 2 Enterprise Goals
A3: Input Section—Importance of Each Enterprise Goal | I3: Input Section—Importance of Each Enterprise Goal
A5: Value | E5: Importance (1-5) | F5: Baseline
A6: EG01—Portfolio of competitive products and services | E6: 2 | F6: 3
A7: EG02—Managed business risk | E7: 4 | F7: 3
A8: EG03—Compliance with external laws and regulations | E8: 5 | F8: 3
A9: EG04—Quality of financial information | E9: 5 | F9: 3
A10: EG05—Customer-oriented service culture | E10: 3 | F10: 3
A11: EG06—Business-service continuity and availability | E11: 5 | F11: 3
A12: EG07—Quality of management information | E12: 4 | F12: 3
A13: EG08—Optimization of internal business process functionality | E13: 3 | F13: 3
A14: EG09—Optimization of business process costs | E14: 4 | F14: 3
A15: EG10—Staff skills, motivation and productivity | E15: 5 | F15: 3
A16: EG11—Compliance with internal policies | E16: 4 | F16: 3
A17: EG12—Managed digital transformation programs | E17: 3 | F17: 3
A18: EG13—Product and business innovation | E18: 2 | F18: 3
E20: Average | F20: =AVERAGE(E6:E18) -> 3.7692308
E21: Stdev | F21: =STDEVP(E6:E18) -> 1.0490909
E22: Correction Factor | F22: =AVERAGE(F6:F18)/F20 -> 0.79591837
A27: Output Section—Resulting relative importance of each governance/management objective | I27: Output Section—Resulting relative importance of each governance/management objective
A29: Resulting Governance/ Management Objectives Importance
A30: Governance / Management Objective | B30: Score | C30: Baseline Score | D30: Relative Importance
A31: EDM01 | B31: =DF2map!C$48 -> 115 | C31: 99 | D31: =IFERROR(MROUND(($F$22*100*B31/C31),5)-100,0) -> -10
A32: EDM02 | B32: =DF2map!D$48 -> 106 | C32: 114 | D32: =IFERROR(MROUND(($F$22*100*B32/C32),5)-100,0) -> -25
A33: EDM03 | B33: =DF2map!E$48 -> 94 | C33: 63 | D33: =IFERROR(MROUND(($F$22*100*B33/C33),5)-100,0) -> 20
A34: EDM04 | B34: =DF2map!F$48 -> 121 | C34: 129 | D34: =IFERROR(MROUND(($F$22*100*B34/C34),5)-100,0) -> -25
A35: EDM05 | B35: =DF2map!G$48 -> 92 | C35: 63 | D35: =IFERROR(MROUND(($F$22*100*B35/C35),5)-100,0) -> 15
A36: APO01 | B36: =DF2map!H$48 -> 213 | C36: 180 | D36: =IFERROR(MROUND(($F$22*100*B36/C36),5)-100,0) -> -5
A37: APO02 | B37: =DF2map!I$48 -> 127 | C37: 132 | D37: =IFERROR(MROUND(($F$22*100*B37/C37),5)-100,0) -> -25
A38: APO03 | B38: =DF2map!J$48 -> 132 | C38: 135 | D38: =IFERROR(MROUND(($F$22*100*B38/C38),5)-100,0) -> -20
A39: APO04 | B39: =DF2map!K$48 -> 109 | C39: 120 | D39: =IFERROR(MROUND(($F$22*100*B39/C39),5)-100,0) -> -30
A40: APO05 | B40: =DF2map!L$48 -> 135 | C40: 141 | D40: =IFERROR(MROUND(($F$22*100*B40/C40),5)-100,0) -> -25
A41: APO06 | B41: =DF2map!M$48 -> 136 | C41: 117 | D41: =IFERROR(MROUND(($F$22*100*B41/C41),5)-100,0) -> -5
A42: APO07 | B42: =DF2map!N$48 -> 106 | C42: 108 | D42: =IFERROR(MROUND(($F$22*100*B42/C42),5)-100,0) -> -20
A43: APO08 | B43: =DF2map!O$48 -> 180 | C43: 189 | D43: =IFERROR(MROUND(($F$22*100*B43/C43),5)-100,0) -> -25
A44: APO09 | B44: =DF2map!P$48 -> 62 | C44: 63 | D44: =IFERROR(MROUND(($F$22*100*B44/C44),5)-100,0) -> -20
A45: APO10 | B45: =DF2map!Q$48 -> 73 | C45: 78 | D45: =IFERROR(MROUND(($F$22*100*B45/C45),5)-100,0) -> -25
A46: APO11 | B46: =DF2map!R$48 -> 150 | C46: 132 | D46: =IFERROR(MROUND(($F$22*100*B46/C46),5)-100,0) -> -10
A47: APO12 | B47: =DF2map!S$48 -> 54 | C47: 36 | D47: =IFERROR(MROUND(($F$22*100*B47/C47),5)-100,0) -> 20
A48: APO13 | B48: =DF2map!T$48 -> 59 | C48: 39 | D48: =IFERROR(MROUND(($F$22*100*B48/C48),5)-100,0) -> 20
...

Sheet DF2map
C2: Agile portfolio of competitive products and services | D2: Managed business risks | E2: Compliance with external laws and regulations | F2: Transparency and accuracy of financial information | G2: Customer-oriented service culture | H2: Business service continuity and availability | I2: Quality of management information | J2: Optimization of internal business process functionality | K2: Optimization of business process costs | L2: Staff skills, motivation and productivity | M2: Compliance with internal policies | N2: Managed business transformation programs | O2: Product and business innovation
C3: ='DF2'!$E6 -> 2 | D3: ='DF2'!$E7 -> 4 | E3: ='DF2'!$E8 -> 5 | F3: ='DF2'!$E9 -> 5 | G3: ='DF2'!$E10 -> 3 | H3: ='DF2'!$E11 -> 5 | I3: ='DF2'!$E12 -> 4 | J3: ='DF2'!$E13 -> 3 | K3: ='DF2'!$E14 -> 4 | L3: ='DF2'!$E15 -> 5 | M3: ='DF2'!$E16 -> 4 | N3: ='DF2'!$E17 -> 3 | O3: ='DF2'!$E18 -> 2
A7: Mapping table EG-GA | C7: AG01 | D7: AG02 | E7: AG03 | F7: AG04 | G7: AG05 | H7: AG06 | I7: AG07 | J7: AG08 | K7: AG09 | L7: AG10 | M7: AG11 | N7: AG12 | O7: AG13
C8: IT compliance and support for business compliance with external laws and regulations | D8: Managed Technology & Information related risks | E8: Realized benefits from IT-enabled investments and services portfolio | F8: Quality of technology related financial information | G8: delivery of IT services in line with business requirements | H8: Agility to turn business requirements into operational solutions | I8: Security of information, processing infrastructure and applications | J8: Enablement and support of business processes by Integrating applications and technology | K8: Delivery of programs on time, on budget, and meeting requirements and quality standards | L8: Quality of IT Management Information | M8: IT compliance with internal policies | N8: Competent and motivated staff with mutual understanding of technology and business. | O8: Knowledge, expertise and initiatives for business innovation
A9: EG01 | B9: Portfolio of agile and competitive products and services | C9: 0 | D9: 0 | E9: 1 | F9: 0 | G9: 2 | H9: 2 | I9: 0 | J9: 2 | K9: 2 | L9: 0 | M9: 0 | N9: 0 | O9: 2
A10: EG02 | B10: Managed business risks | C10: 1 | D10: 2 | E10: 0 | F10: 0 | G10: 0 | H10: 0 | I10: 1 | J10: 0 | K10: 0 | L10: 0 | M10: 1 | N10: 0 | O10: 0
A11: EG03 | B11: Compliance with external laws and regulations | C11: 2 | D11: 0 | E11: 0 | F11: 0 | G11: 0 | H11: 0 | I11: 0 | J11: 0 | K11: 0 | L11: 0 | M11: 2 | N11: 0 | O11: 0
A12: EG04 | B12: Transparency and accuracy of financial information | C12: 0 | D12: 0 | E12: 0 | F12: 2 | G12: 0 | H12: 0 | I12: 0 | J12: 0 | K12: 0 | L12: 2 | M12: 0 | N12: 0 | O12: 0
A13: EG05 | B13: Customer-oriented service culture | C13: 0 | D13: 0 | E13: 1 | F13: 0 | G13: 1 | H13: 1 | I13: 0 | J13: 2 | K13: 1 | L13: 0 | M13: 0 | N13: 1 | O13: 0
A14: EG06 | B14: Business service continuity and availability | C14: 0 | D14: 1 | E14: 0 | F14: 0 | G14: 1 | H14: 0 | I14: 2 | J14: 0 | K14: 0 | L14: 0 | M14: 0 | N14: 0 | O14: 0
A15: EG07 | B15: Accuracy (Quality?) of Management Information | C15: 0 | D15: 0 | E15: 0 | F15: 2 | G15: 0 | H15: 0 | I15: 0 | J15: 0 | K15: 0 | L15: 2 | M15: 0 | N15: 0 | O15: 0
A16: EG08 | B16: Optimization of business process functionality | C16: 0 | D16: 0 | E16: 1 | F16: 0 | G16: 1 | H16: 1 | I16: 0 | J16: 1 | K16: 1 | L16: 0 | M16: 0 | N16: 0 | O16: 0
A17: EG09 | B17: Optimization of business process costs | C17: 0 | D17: 0 | E17: 1 | F17: 2 | G17: 0 | H17: 0 | I17: 0 | J17: 0 | K17: 1 | L17: 1 | M17: 0 | N17: 0 | O17: 0
A18: EG10 | B18: Staff skills, motivation and productivity | C18: 0 | D18: 0 | E18: 0 | F18: 0 | G18: 0 | H18: 0 | I18: 0 | J18: 1 | K18: 0 | L18: 0 | M18: 0 | N18: 2 | O18: 0
A19: EG11 | B19: Compliance with internal policies | C19: 1 | D19: 0 | E19: 0 | F19: 0 | G19: 0 | H19: 0 | I19: 0 | J19: 0 | K19: 0 | L19: 0 | M19: 2 | N19: 0 | O19: 0
A20: EG12 | B20: Managed business transformation programs | C20: 0 | D20: 0 | E20: 2 | F20: 0 | G20: 1 | H20: 1 | I20: 0 | J20: 2 | K20: 2 | L20: 0 | M20: 0 | N20: 0 | O20: 1
A21: EG13 | B21: Product and business innovation | C21: 0 | D21: 0 | E21: 0 | F21: 0 | G21: 0 | H21: 1 | I21: 0 | J21: 1 | K21: 1 | L21: 0 | M21: 0 | N21: 0 | O21: 2
C24: AG01 | D24: AG02 | E24: AG03 | F24: AG04 | G24: AG05 | H24: AG06 | I24: AG07 | J24: AG08 | K24: AG09 | L24: AG10 | M24: AG11 | N24: AG12 | O24: AG13
C25: IT compliance and support for business compliance with external laws and regulations | D25: Managed Technology & Information related risks | E25: Realized benefits from IT-enabled investments and services portfolio | F25: Quality of technology related financial information | G25: delivery of IT services in line with business requirements | H25: Agility to turn business requirements into operational solutions | I25: Security of information, processing infrastructure and applications | J25: Enablement and support of business processes by Integrating applications and technology | K25: Delivery of programs on time, on budget, and meeting requirements and quality standards | L25: Quality of IT Management Information | M25: IT compliance with internal policies | N25: Competent and motivated staff with mutual understanding of technology and business. | O25: Knowledge, expertise and initiatives for business innovation
C26: {=MMULT(C3:O3,C9:O21)} -> 18 | D26: 13 | E26: 18 | F26: 26 | G26: 18 | H26: 15 | I26: 14 | J26: 26 | K26: 22 | L26: 22 | M26: 22 | N26: 13 | O26: 11
A29: Mapping Table AG-GMO | C29: EDM01 | D29: EDM02 | E29: EDM03 | F29: EDM04 | G29: EDM05 | H29: APO01 | I29: APO02 | J29: APO03 | K29: APO04 | L29: APO05 | M29: APO06 | N29: APO07 | O29: APO08 | P29: APO09 | Q29: APO10 | R29: APO11 | S29: APO12 | T29: APO13 | U29: APO14 | V29: BAI01 | W29: BAI02 | X29: BAI03 | Y29: BAI04 | Z29: BAI05 | AA29: BAI06 | AB29: BAI07 | AC29: BAI08 | AD29: BAI09 | AE29: BAI10 | AF29: BAI11 | AG29: DSS01 | AH29: DSS02 | AI29: DSS03 | AJ29: DSS04 | AK29: DSS05 | AL29: DSS06 | AM29: MEA01 | AN29: MEA02 | AO29: MEA03 | AP29: MEA04
C30: Ensured Governance Framework Setting & Maintenance | D30: Ensured Benefits Delivery | E30: Ensured Risk Optimization | F30: Ensured Resource Optimization | G30: Ensured Stakeholder Transparency | H30: Managed IT Management Framework | I30: Managed Strategy | J30: Managed Architecture | K30: Managed Innovation | L30: Managed Portfolio | M30: Managed Budget & Costs | N30: Managed Human Resources | O30: Managed Relationships | P30: Managed Service Agreements | Q30: Managed Suppliers | R30: Managed Quality | S30: Managed Risk | T30: Managed Information Security | U30: Managed Data | V30: Managed Programs | W30: Managed Requirements Definition | X30: Managed Solutions Identification & Build | Y30: Managed Availability & Capacity | Z30: Managed Organizational Change | AA30: Managed IT Changes | AB30: Managed IT Change Acceptance & Transitioning | AC30: Managed Knowledge | AD30: Managed Assets | AE30: Managed Configuration | AF30: Managed Projects | AG30: Managed Operations | AH30: Managed Service Requests & Incidents | AI30: Managed Problems | AJ30: Managed Continuity | AK30: Managed Security Services | AL30: Managed Business Process Controls | AM30: Managed Performance & Conformance Monitoring | AN30: Managed System of Internal Control | AO30: Managed Compliance with External Requirements | AP30: Managed Internal Audit
A31: AG01 | B31: IT compliance and support for business compliance with external laws and regulations | C31: 1 | D31: 0 | E31: 1 | F31: 0 | G31: 0 | H31: 1 | I31: 0 | J31: 0 | K31: 0 | L31: 0 | M31: 0 | N31: 0 | O31: 0 | P31: 0 | Q31: 0 | R31: 0 | S31: 0 | T31: 1 | U31: 1 | V31: 0 | W31: 0 | X31: 0 | Y31: 0 | Z31: 0 | AA31: 0 | AB31: 0 | AC31: 0 | AD31: 0 | AE31: 0 | AF31: 0 | AG31: 0 | AH31: 0 | AI31: 0 | AJ31: 0 | AK31: 1 | AL31: 0 | AM31: 1 | AN31: 1 | AO31: 2 | AP31: 1
A32: AG02 | B32: Managed Technology & Information related risks | C32: 1 | D32: 0 | E32: 2 | F32: 0 | G32: 0 | H32: 1 | I32: 0 | J32: 0 | K32: 0 | L32: 0 | M32: 0 | N32: 0 | O32: 0 | P32: 0 | Q32: 0 | R32: 0 | S32: 2 | T32: 1 | U32: 1 | V32: 0 | W32: 0 | X32: 0 | Y32: 0 | Z32: 0 | AA32: 1 | AB32: 1 | AC32: 0 | AD32: 0 | AE32: 0 | AF32: 0 | AG32: 0 | AH32: 1 | AI32: 1 | AJ32: 1 | AK32: 2 | AL32: 1 | AM32: 0 | AN32: 1 | AO32: 0 | AP32: 1
A33: AG03 | B33: Realized benefits from IT-enabled investments and services portfolio | C33: 2 | D33: 2 | E33: 0 | F33: 1 | G33: 0 | H33: 2 | I33: 1 | J33: 1 | K33: 1 | L33: 2 | M33: 1 | N33: 1 | O33: 1 | P33: 0 | Q33: 0 | R33: 1 | S33: 0 | T33: 0 | U33: 0 | V33: 2 | W33: 1 | X33: 1 | Y33: 0 | Z33: 2 | AA33: 0 | AB33: 0 | AC33: 1 | AD33: 0 | AE33: 0 | AF33: 2 | AG33: 0 | AH33: 0 | AI33: 0 | AJ33: 0 | AK33: 0 | AL33: 0 | AM33: 1 | AN33: 0 | AO33: 0 | AP33: 0
A34: AG04 | B34: Quality of technology related financial information | C34: 0 | D34: 0 | E34: 0 | F34: 0 | G34: 1 | H34: 0 | I34: 0 | J34: 0 | K34: 0 | L34: 0 | M34: 2 | N34: 0 | O34: 0 | P34: 0 | Q34: 0 | R34: 1 | S34: 0 | T34: 0 | U34: 1 | V34: 0 | W34: 0 | X34: 0 | Y34: 0 | Z34: 0 | AA34: 0 | AB34: 0 | AC34: 0 | AD34: 2 | AE34: 0 | AF34: 0 | AG34: 0 | AH34: 0 | AI34: 0 | AJ34: 0 | AK34: 0 | AL34: 0 | AM34: 0 | AN34: 1 | AO34: 0 | AP34: 1
A35: AG05 | B35: Delivery of IT services in line with business requirements | C35: 0 | D35: 1 | E35: 0 | F35: 1 | G35: 0 | H35: 1 | I35: 1 | J35: 1 | K35: 0 | L35: 2 | M35: 0 | N35: 1 | O35: 2 | P35: 2 | Q35: 2 | R35: 1 | S35: 0 | T35: 0 | U35: 0 | V35: 0 | W35: 2 | X35: 2 | Y35: 2 | Z35: 1 | AA35: 1 | AB35: 0 | AC35: 0 | AD35: 0 | AE35: 1 | AF35: 1 | AG35: 2 | AH35: 2 | AI35: 2 | AJ35: 2 | AK35: 1 | AL35: 1 | AM35: 2 | AN35: 1 | AO35: 0 | AP35: 1
A36: AG06 | B36: Agility to turn business requirements into operational solutions | C36: 0 | D36: 1 | E36: 0 | F36: 1 | G36: 0 | H36: 0 | I36: 1 | J36: 2 | K36: 2 | L36: 1 | M36: 0 | N36: 0 | O36: 2 | P36: 0 | Q36: 1 | R36: 0 | S36: 0 | T36: 0 | U36: 0 | V36: 1 | W36: 2 | X36: 2 | Y36: 0 | Z36: 1 | AA36: 2 | AB36: 2 | AC36: 1 | AD36: 0 | AE36: 0 | AF36: 2 | AG36: 0 | AH36: 0 | AI36: 0 | AJ36: 0 | AK36: 0 | AL36: 0 | AM36: 0 | AN36: 0 | AO36: 0 | AP36: 0
A37: AG07 | B37: Security of information, processing infrastructure and applications | C37: 0 | D37: 0 | E37: 2 | F37: 0 | G37: 0 | H37: 1 | I37: 0 | J37: 1 | K37: 0 | L37: 0 | M37: 0 | N37: 0 | O37: 0 | P37: 0 | Q37: 0 | R37: 0 | S37: 2 | T37: 2 | U37: 1 | V37: 0 | W37: 0 | X37: 0 | Y37: 1 | Z37: 0 | AA37: 0 | AB37: 0 | AC37: 0 | AD37: 0 | AE37: 0 | AF37: 0 | AG37: 0 | AH37: 1 | AI37: 1 | AJ37: 1 | AK37: 2 | AL37: 1 | AM37: 0 | AN37: 1 | AO37: 0 | AP37: 1
A38: AG08 | B38: Enablement and support of business processes by Integrating applications and technology | C38: 1 | D38: 1 | E38: 0 | F38: 1 | G38: 0 | H38: 1 | I38: 2 | J38: 2 | K38: 1 | L38: 1 | M38: 0 | N38: 0 | O38: 1 | P38: 1 | Q38: 0 | R38: 0 | S38: 0 | T38: 0 | U38: 0 | V38: 1 | W38: 1 | X38: 1 | Y38: 0 | Z38: 2 | AA38: 1 | AB38: 0 | AC38: 1 | AD38: 0 | AE38: 0 | AF38: 0 | AG38: 1 | AH38: 0 | AI38: 0 | AJ38: 0 | AK38: 0 | AL38: 2 | AM38: 0 | AN38: 0 | AO38: 0 | AP38: 0
A39: AG09 | B39: Delivery of programs on time, on budget, and meeting requirements and quality standards | C39: 0 | D39: 0 | E39: 0 | F39: 2 | G39: 0 | H39: 1 | I39: 0 | J39: 0 | K39: 0 | L39: 1 | M39: 2 | N39: 1 | O39: 1 | P39: 0 | Q39: 1 | R39: 2 | S39: 0 | T39: 0 | U39: 0 | V39: 2 | W39: 2 | X39: 2 | Y39: 1 | Z39: 2 | AA39: 0 | AB39: 1 | AC39: 1 | AD39: 0 | AE39: 0 | AF39: 2 | AG39: 0 | AH39: 0 | AI39: 0 | AJ39: 0 | AK39: 0 | AL39: 0 | AM39: 1 | AN39: 1 | AO39: 0 | AP39: 0
A40: AG10 | B40: Quality of IT Management Information | C40: 0 | D40: 0 | E40: 0 | F40: 0 | G40: 2 | H40: 1 | I40: 0 | J40: 0 | K40: 0 | L40: 0 | M40: 1 | N40: 0 | O40: 0 | P40: 0 | Q40: 0 | R40: 2 | S40: 0 | T40: 0 | U40: 2 | V40: 0 | W40: 0 | X40: 0 | Y40: 0 | Z40: 0 | AA40: 0 | AB40: 0 | AC40: 0 | AD40: 1 | AE40: 0 | AF40: 0 | AG40: 0 | AH40: 0 | AI40: 0 | AJ40: 0 | AK40: 0 | AL40: 0 | AM40: 2 | AN40: 1 | AO40: 0 | AP40: 1
A41: AG11 | B41: IT compliance with internal policies | C41: 1 | D41: 0 | E41: 1 | F41: 0 | G41: 1 | H41: 2 | I41: 0 | J41: 0 | K41: 0 | L41: 0 | M41: 0 | N41: 0 | O41: 0 | P41: 0 | Q41: 0 | R41: 0 | S41: 0 | T41: 0 | U41: 0 | V41: 0 | W41: 0 | X41: 0 | Y41: 0 | Z41: 0 | AA41: 0 | AB41: 0 | AC41: 0 | AD41: 0 | AE41: 0 | AF41: 0 | AG41: 0 | AH41: 0 | AI41: 0 | AJ41: 0 | AK41: 1 | AL41: 1 | AM41: 1 | AN41: 2 | AO41: 1 | AP41: 2
A42: AG12 | B42: Competent and motivated staff with mutual understanding of technology and business. | C42: 0 | D42: 0 | E42: 0 | F42: 0 | G42: 0 | H42: 0 | I42: 1 | J42: 0 | K42: 1 | L42: 0 | M42: 0 | N42: 2 | O42: 2 | P42: 0 | Q42: 0 | R42: 0 | S42: 0 | T42: 0 | U42: 0 | V42: 0 | W42: 1 | X42: 0 | Y42: 0 | Z42: 1 | AA42: 0 | AB42: 0 | AC42: 2 | AD42: 0 | AE42: 0 | AF42: 0 | AG42: 0 | AH42: 0 | AI42: 0 | AJ42: 0 | AK42: 0 | AL42: 0 | AM42: 0 | AN42: 0 | AO42: 0 | AP42: 0
A43: AG13 | B43: Knowledge, expertise and initiatives for business innovation | C43: 0 | D43: 1 | E43: 0 | F43: 0 | G43: 0 | H43: 0 | I43: 1 | J43: 0 | K43: 2 | L43: 0 | M43: 0 | N43: 2 | O43: 2 | P43: 0 | Q43: 0 | R43: 0 | S43: 0 | T43: 0 | U43: 0 | V43: 0 | W43: 0 | X43: 0 | Y43: 0 | Z43: 0 | AA43: 0 | AB43: 0 | AC43: 2 | AD43: 0 | AE43: 0 | AF43: 0 | AG43: 0 | AH43: 0 | AI43: 0 | AJ43: 0 | AK43: 0 | AL43: 0 | AM43: 0 | AN43: 0 | AO43: 0 | AP43: 0
C46: EDM01 | D46: EDM02 | E46: EDM03 | F46: EDM04 | G46: EDM05 | H46: APO01 | I46: APO02 | J46: APO03 | K46: APO04 | L46: APO05 | M46: APO06 | N46: APO07 | O46: APO08 | P46: APO09 | Q46: APO10 | R46: APO11 | S46: APO12 | T46: APO13 | U46: APO14 | V46: BAI01 | W46: BAI02 | X46: BAI03 | Y46: BAI04 | Z46: BAI05 | AA46: BAI06 | AB46: BAI07 | AC46: BAI08 | AD46: BAI09 | AE46: BAI10 | AF46: BAI11 | AG46: DSS01 | AH46: DSS02 | AI46: DSS03 | AJ46: DSS04 | AK46: DSS05 | AL46: DSS06 | AM46: MEA01 | AN46: MEA02 | AO46: MEA03 | AP46: MEA04
C47: Ensured Governance Framework Setting & Maintenance | D47: Ensured Benefits Delivery | E47: Ensured Risk Optimization | F47: Ensured Resource Optimization | G47: Ensured Stakeholder Transparency | H47: Managed IT Management Framework | I47: Managed Strategy | J47: Managed Architecture | K47: Managed Innovation | L47: Managed Portfolio | M47: Managed Budget & Costs | N47: Managed Human Resources | O47: Managed Relationships | P47: Managed Service Agreements | Q47: Managed Suppliers | R47: Managed Quality | S47: Managed Risk | T47: Managed Information Security | U47: Managed Data | V47: Managed Programs | W47: Managed Requirements Definition | X47: Managed Solutions Identification & Build | Y47: Managed Availability & Capacity | Z47: Managed Organizational Change | AA47: Managed IT Changes | AB47: Managed IT Change Acceptance & Transitioning | AC47: Managed Knowledge | AD47: Managed Assets | AE47: Managed Configuration | AF47: Managed Projects | AG47: Managed Operations | AH47: Managed Service Requests & Incidents | AI47: Managed Problems | AJ47: Managed Continuity | AK47: Managed Security Services | AL47: Managed Business Process Controls | AM47: Managed Performance & Conformance Monitoring | AN47: Managed System of Internal Control | AO47: Managed Compliance with External Requirements | AP47: Managed Internal Audit
C48: {=MMULT(C26:O26,C31:AP43)} -> 115 | D48: 106 | E48: 94 | F48: 121 | G48: 92 | H48: 213 | I48: 127 | J48: 132 | K48: 109 | L48: 135 | M48: 136 | N48: 106 | O48: 180 | P48: 62 | Q48: 73 | R48: 150 | S48: 54 | T48: 59 | U48: 115 | V48: 121 | W48: 167 | X48: 154 | Y48: 72 | Z48: 178 | AA48: 87 | AB48: 65 | AC48: 129 | AD48: 74 | AE48: 18 | AF48: 128 | AG48: 62 | AH48: 63 | AI48: 63 | AJ48: 63 | AK48: 112 | AL48: 119 | AM48: 160 | AN48: 177 | AO48: 58 | AP48: 155
B49: Baseline | C49: 99 | D49: 114 | E49: 63 | F49: 129 | G49: 63 | H49: 180 | I49: 132 | J49: 135 | K49: 120 | L49: 141 | M49: 117 | N49: 108 | O49: 189 | P49: 63 | Q49: 78 | R49: 132 | S49: 36 | T49: 39 | U49: 78 | V49: 129 | W49: 174 | X49: 165 | Y49: 69 | Z49: 183 | AA49: 90 | AB49: 69 | AC49: 135 | AD49: 51 | AE49: 18 | AF49: 138 | AG49: 63 | AH49: 54 | AI49: 54 | AJ49: 54 | AK49: 81 | AL49: 105 | AM49: 135 | AN49: 135 | AO49: 39 | AP49: 111
B50: Imp® | C50: =TRUNC(100*C48/C49)-100 -> 16 | D50: =TRUNC(100*D48/D49)-100 -> -8 | E50: =TRUNC(100*E48/E49)-100 -> 49 | F50: =TRUNC(100*F48/F49)-100 -> -7 | G50: =TRUNC(100*G48/G49)-100 -> 46 | H50: =TRUNC(100*H48/H49)-100 -> 18 | I50: =TRUNC(100*I48/I49)-100 -> -4 | J50: =TRUNC(100*J48/J49)-100 -> -3 | ... AP50: =TRUNC(100*AP48/AP49)-100 -> 39

Sheet DF3
A1: Information & Technology Governance System Design Design Factor 3 Risk Profile | L1: Information & Technology Governance System Design Design Factor 3 Risk Profile
A3: Input Section—Importance of Each Generic IT Risk Category | M3: Input Section—Importance of Each Generic IT Risk Category
A5: Risk Scenario Category | E5: Impact (1-5) | F5: Likelihood (1-5) | G5: Risk Rating | H5: Baseline
A6: IT investment decision making, portfolio definition & maintenance | E6: 4 | F6: 3 | G6: =E6*F6 -> 12 | H6: 9 | J6: 16 | K6: Very High Risk
A7: Program & projects life cycle management | E7: 5 | F7: 2 | G7: =E7*F7 -> 10 | H7: 9 | J7: 12 | K7: High Risk
A8: IT cost & oversight | E8: 2 | F8: 2 | G8: =E8*F8 -> 4 | H8: 9 | J8: 6 | K8: Normal Risk
A9: IT expertise, skills & behavior | E9: 4 | F9: 3 | G9: =E9*F9 -> 12 | H9: 9 | J9: 0 | K9: Low Risk
A10: Enterprise/IT architecture | E10: 2 | F10: 4 | G10: =E10*F10 -> 8 | H10: 9
A11: IT operational infrastructure incidents | E11: 5 | F11: 5 | G11: =E11*F11 -> 25 | H11: 9
A12: Unauthorized actions | E12: 4 | F12: 3 | G12: =E12*F12 -> 12 | H12: 9
A13: Software adoption/usage problems | E13: 4 | F13: 3 | G13: =E13*F13 -> 12 | H13: 9
A14: Hardware incidents | E14: 4 | F14: 3 | G14: =E14*F14 -> 12 | H14: 9
A15: Software failures | E15: 4 | F15: 3 | G15: =E15*F15 -> 12 | H15: 9
A16: Logical attacks (hacking, malware, etc.) | E16: 5 | F16: 5 | G16: =E16*F16 -> 25 | H16: 9
A17: Third-party/supplier incidents | E17: 2 | F17: 2 | G17: =E17*F17 -> 4 | H17: 9
A18: Noncompliance | E18: 3 | F18: 3 | G18: =E18*F18 -> 9 | H18: 9
A19: Geopolitical Issues | E19: 2 | F19: 1 | G19: =E19*F19 -> 2 | H19: 9
A20: Industrial action | E20: 1 | F20: 3 | G20: =E20*F20 -> 3 | H20: 9
A21: Acts of nature | E21: 3 | F21: 3 | G21: =E21*F21 -> 9 | H21: 9
... A24: Data & information management | E24: 5 | F24: 4 | G24: =E24*F24 -> 20 | H24: 9
A26: Average | G26: =AVERAGE(G6:G24) -> 10.736842
A27: Stdev | G27: =STDEVP(G6:G24) -> 6.4550438
A28: Correction Factor | G28: =AVERAGE(H6:H24)/G26 -> 0.83823529
A31: Output Section—Resulting relative importance of each governance/management objective | L31: Output Section—Resulting relative importance of each governance/management objective
A33: Resulting Governance/Management Objectives Importance
A34: Governance / Management Objective | B34: Score | C34: Baseline Score | D34: Relative Importance
A35: EDM01 | B35: {=MMULT(DF3map!B3:T42,'DF3'!G6:G24)} -> 189 | C35: {=MMULT(DF3map!B3:T42,'DF3'!H6:H24)} -> 189 | D35: =IFERROR(MROUND(($G$28*100*B35/C35),5)-100,0) -> -15
A36: EDM02 | B36: 172 | C36: 135 | D36: =IFERROR(MROUND(($G$28*100*B36/C36),5)-100,0) -> 5
A37: EDM03 | B37: 207 | C37: 162 | D37: =IFERROR(MROUND(($G$28*100*B37/C37),5)-100,0) -> 5
A38: EDM04 | B38: 195 | C38: 198 | D38: =IFERROR(MROUND(($G$28*100*B38/C38),5)-100,0) -> -15
A39: EDM05 | B39: 179 | C39: 189 | D39: =IFERROR(MROUND(($G$28*100*B39/C39),5)-100,0) -> -20
A40: APO01 | B40: 433 | C40: 324 | D40: =IFERROR(MROUND(($G$28*100*B40/C40),5)-100,0) -> 10
A41: APO02 | B41: 163 | C41: 144 | D41: =IFERROR(MROUND(($G$28*100*B41/C41),5)-100,0) -> -5
A42: APO03 | B42: 240 | C42: 171 | D42: =IFERROR(MROUND(($G$28*100*B42/C42),5)-100,0) -> 20
A43: APO04 | B43: 44 | C43: 45 | D43: =IFERROR(MROUND(($G$28*100*B43/C43),5)-100,0) -> -20
A44: APO05 | B44: 158 | C44: 144 | D44: =IFERROR(MROUND(($G$28*100*B44/C44),5)-100,0) -> -10
A45: APO06 | B45: 108 | C45: 153 | D45: =IFERROR(MROUND(($G$28*100*B45/C45),5)-100,0) -> -40
A46: APO07 | B46: 262 | C46: 216 | D46: =IFERROR(MROUND(($G$28*100*B46/C46),5)-100,0) -> 0
A47: APO08 | B47: 213 | C47: 153 | D47: =IFERROR(MROUND(($G$28*100*B47/C47),5)-100,0) -> 15
... A74: MEA04 | B74: 277 | C74: 225 | D74: =IFERROR(MROUND(($G$28*100*B74/C74),5)-100,0) -> 5

Sheet DF3map
A1: DF3 | B1: 1 | C1: 2 | D1: 3 | E1: 4 | F1: 5 | G1: 6 | H1: 7 | I1: 8 | J1: 9 | K1: 10 | L1: 11 | M1: 12 | N1: 13 | O1: 14 | P1: 15 | Q1: 16 | R1: 17 | S1: 18 | T1: 19
B2: IT Investment Decision Making, Portfolio Definition & Maintenance | C2: Program & Projects Life Cycle Management | D2: IT Cost & Oversight | E2: IT Expertise, Skills & Behavior | F2: Enterprise/ IT Architecture | G2: IT Operational Infrastructure Incidents | H2: Unauthorized Actions | I2: Software Adoption/ Usage Problems | J2: Hardware Incidents | K2: Software Failures | L2: Logical Attacks (Hacking, Malware, etc.) | M2: Third-Party/ Supplier Incidents | N2: Noncompliance | O2: Geopolitical Issues | P2: Industrial Action | Q2: Acts of Nature | R2: Technology-Based Innovation | S2: Environmental | T2: Data & Information Management
A3: EDM01 | B3: 3 | C3: 2 | D3: 3 | E3: 0 | F3: 0 | G3: 0 | H3: 2 | I3: 0 | J3: 0 | K3: 0 | L3: 0 | M3: 0 | N3: 3 | O3: 2 | P3: 0 | Q3: 0 | R3: 2 | S3: 2 | T3: 2
A4: EDM02 | B4: 3 | C4: 2 | D4: 0 | E4: 0 | F4: 2 | G4: 0 | H4: 0 | I4: 0 | J4: 0 | K4: 0 | L4: 0 | M4: 0 | N4: 1 | O4: 0 | P4: 0 | Q4: 0 | R4: 3 | S4: 1 | T4: 3
A5: EDM03 | B5: 2 | C5: 2 | D5: 0 | E5: 0 | F5: 0 | G5: 0 | H5: 0 | I5: 0 | J5: 0 | K5: 1 | L5: 2 | M5: 0 | N5: 3 | O5: 3 | P5: 0 | Q5: 0 | R5: 0 | S5: 2 | T5: 3
A6: EDM04 | B6: 3 | C6: 0 | D6: 4 | E6: 3 | F6: 2 | G6: 0 | H6: 0 | I6: 0 | J6: 0 | K6: 0 | L6: 0 | M6: 2 | N6: 1 | O6: 0 | P6: 2 | Q6: 0 | R6: 0 | S6: 2 | T6: 3
A7: EDM05 | B7: 3 | C7: 1 | D7: 3 | E7: 0 | F7: 0 | G7: 0 | H7: 2 | I7: 0 | J7: 0 | K7: 1 | L7: 0 | M7: 1 | N7: 3 | O7: 3 | P7: 0 | Q7: 0 | R7: 0 | S7: 2 | T7: 2
A8: APO01 | B8: 2 | C8: 3 | D8: 2 | E8: 0 | F8: 2 | G8: 2 | H8: 4 | I8: 2 | J8: 0 | K8: 2 | L8: 3 | M8: 3 | N8: 3 | O8: 0 | P8: 0 | Q8: 0 | R8: 3 | S8: 2 | T8: 3
A9: APO02 | B9: 2 | C9: 0 | D9: 0 | E9: 0 | F9: 3 | G9: 0 | H9: 0 | I9: 2 | J9: 1 | K9: 0 | L9: 1 | M9: 2 | N9: 0 | O9: 0 | P9: 0 | Q9: 0 | R9: 2 | S9: 2 | T9: 1
A10: APO03 | B10: 2 | C10: 0 | D10: 0 | E10: 0 | F10: 4 | G10: 0 | H10: 0 | I10: 2 | J10: 0 | K10: 2 | L10: 2 | M10: 2 | N10: 0 | O10: 0 | P10: 0 | Q10: 0 | R10: 2 | S10: 0 | T10: 3
A11: APO04 | B11: 0 | C11: 0 | D11: 0 | E11: 0 | F11: 1 | G11: 0 | H11: 0 | I11: 0 | J11: 0 | K11: 0 | L11: 0 | M11: 0 | N11: 0 | O11: 0 | P11: 0 | Q11: 0 | R11: 4 | S11: 0 | T11: 0
A12: APO05 | B12: 4 | C12: 2 | D12: 2 | E12: 0 | F12: 2 | G12: 0 | H12: 0 | I12: 2 | J12: 2 | K12: 0 | L12: 0 | M12: 0 | N12: 0 | O12: 0 | P12: 0 | Q12: 0 | R12: 2 | S12: 0 | T12: 0
A13: APO06 | B13: 2 | C13: 3 | D13: 4 | E13: 0 | F13: 0 | G13: 0 | H13: 0 | I13: 0 | J13: 0 | K13: 0 | L13: 0 | M13: 2 | N13: 0 | O13: 2 | P13: 0 | Q13: 0 | R13: 2 | S13: 2 | T13: 0
A14: APO07 | B14: 0 | C14: 0 | D14: 0 | E14: 4 | F14: 0 | G14: 2 | H14: 3 | I14: 3 | J14: 0 | K14: 0 | L14: 2 | M14: 0 | N14: 0 | O14: 2 | P14: 4 | Q14: 0 | R14: 2 | S14: 2 | T14: 0
... A42: MEA04 | B42: 1 | C42: 2 | D42: 0 | E42: 0 | F42: 0 | G42: 0 | H42: 3 | I42: 0 | J42: 0 | K42: 2 | L42: 3 | M42: 2 | N42: 2 | O42: 4 | P42: 0 | Q42: 2 | R42: 2 | S42: 0 | T42: 2

Sheet DF4
A1: Information & Technology Governance System Design Design Factor 4 I&T-Related Issues | K1: Information & Technology Governance System Design Design Factor 4 I&T-Related Issues
A3: Input Section—Importance of Each Generic I&T-Related Issue | K3: Input Section—Importance of Each Generic I&T-Related Issue
A5: I&T-Related Issue | F5: Importance (1-3) | G5: Baseline
A6: Frustration between different IT entities across the organization because of a perception of low contribution to business value | F6: 3 | G6: 2 | I6: 1 | J6: No Issue
A7: Frustration between business departments (i.e., the IT customer) and the IT department because of failed initiatives or a perception of low contribution to business value | F7: 2 | G7: 2 | I7: 2 | J7: Issue
A8: Significant I&T-related incidents, such as data loss, security breaches, project failure and application errors, linked to IT | F8: 3 | G8: 2 | I8: 3 | J8: Serious Issue
A9: Service delivery problems by the IT outsourcer(s) | F9: 2 | G9: 2
A10: Failures to meet IT-related regulatory or contractual requirements | F10: 2 | G10: 2
A11: Regular audit findings or other assessment reports about poor IT performance or reported IT quality or service problems | F11: 1 | G11: 2
A12: Substantial hidden and rogue IT spending, that is, I&T spending by user departments outside the control of the normal I&T investment decision mechanisms and approved budgets | F12: 2 | G12: 2
A13: Duplications or overlaps between various initiatives, or other forms of wasted resources | F13: 3 | G13: 2
A14: Insufficient IT resources, staff with inadequate skills or staff burnout/dissatisfaction | F14: 2 | G14: 2
A15: IT-enabled changes or projects frequently failing to meet business needs and delivered late or over budget | F15: 2 | G15: 2
A16: Reluctance by board members, executives or senior management to engage with IT, or a lack of committed business sponsorship for IT | F16: 1 | G16: 2
A17: Complex IT operating model and/or unclear decision mechanisms for IT-related decisions | F17: 2 | G17: 2
A18: Excessively high cost of IT | F18: 1 | G18: 2
A19: Obstructed or failed implementation of new initiatives or innovations caused by the current IT architecture and systems | F19: 2 | G19: 2
A20: Gap between business and technical knowledge, which leads to business users and information and/or technology specialists speaking different languages | F20: 2 | G20: 2
... A22: High level of end-user computing, creating (among other problems) a lack of oversight and quality control over the applications that are being developed and put in operation | F22: 1 | G22: 2
A23: Business departments implementing their own information solutions with little or no involvement of the enterprise IT department (related to end-user computing, which often stems from dissatisfaction with IT solutions and services) | F23: 2 | G23: 2 | I23: Average | J23: =AVERAGE(F6:F25) -> 1.95
A24: Ignorance of and/or noncompliance with privacy regulations | F24: 2 | G24: 2 | I24: Stdev | J24: =STDEVP(F6:F25) -> 0.66895441
A25: Inability to exploit new technologies or innovate using I&T | F25: 1 | G25: 2 | I25: Correction Factor | J25: =AVERAGE(G6:G25)/J23 -> 1.025641
A27: Output Section—Resulting relative importance of each governance/management objective | K27: Output Section—Resulting relative importance of each governance/management objective
A29: Resulting Governance/ Management Objectives Importance
A30: Governance / Management Objective | B30: Score | C30: Baseline Score | D30: Relative Importance
A31: EDM01 | B31: {=MMULT(DF4map!B2:U41,'DF4'!F6:F25)} -> 67 | C31: {=MMULT(DF4map!B2:U41,'DF4'!G6:G25)} -> 70 | D31: =IFERROR(MROUND(($J$25*100*B31/C31),5)-100,0) -> 0
A32: EDM02 | B32: 64.5 | C32: 70 | D32: =IFERROR(MROUND(($J$25*100*B32/C32),5)-100,0) -> -5
A33: EDM03 | B33: 47 | C33: 47 | D33: =IFERROR(MROUND(($J$25*100*B33/C33),5)-100,0) -> 5
A34: EDM04 | B34: 63.5 | C34: 67 | D34: =IFERROR(MROUND(($J$25*100*B34/C34),5)-100,0) -> -5
A35: EDM05 | B35: 37 | C35: 41 | D35: =IFERROR(MROUND(($J$25*100*B35/C35),5)-100,0) -> -5
A36: APO01 | B36: 55 | C36: 56 | D36: =IFERROR(MROUND(($J$25*100*B36/C36),5)-100,0) -> 0
A37: APO02 | B37: 45.5 | C37: 50 | D37: =IFERROR(MROUND(($J$25*100*B37/C37),5)-100,0) -> -5
A38: APO03 | B38: 66 | C38: 66 | D38: =IFERROR(MROUND(($J$25*100*B38/C38),5)-100,0) -> 5
A39: APO04 | B39: 28.5 | C39: 32 | D39: =IFERROR(MROUND(($J$25*100*B39/C39),5)-100,0) -> -10
A40: APO05 | B40: 65 | C40: 68 | D40: =IFERROR(MROUND(($J$25*100*B40/C40),5)-100,0) -> 0
A41: APO06 | B41: 61.5 | C41: 62 | D41: =IFERROR(MROUND(($J$25*100*B41/C41),5)-100,0) -> 0
A42: APO07 | B42: 47.5 | C42: 47 | D42: =IFERROR(MROUND(($J$25*100*B42/C42),5)-100,0) -> 5
A43: APO08 | B43: 68.5 | C43: 70 | D43: =IFERROR(MROUND(($J$25*100*B43/C43),5)-100,0) -> 0
... A70: MEA04 | B70: 55.5 | C70: 58 | D70: =IFERROR(MROUND(($J$25*100*B70/C70),5)-100,0) -> 0

Sheet DF4map
A1: DF4 | B1: Frustration between different IT entities across the organization because of a perception of low contribution to business value | C1: Frustration between business departments (i.e., the IT customer) and the IT department because of failed initiatives or a perception of low contribution to business value | D1: Significant IT-related incidents, such as data loss, security breaches, project failure and application errors, linked to IT | E1: Service delivery problems by the IT outsourcer(s) | F1: Failures to meet IT-related regulatory or contractual requirements | G1: Regular audit findings or other assessment reports about poor IT performance or reported IT quality or service problems | H1: Substantial hidden and rogue IT spending, that is, IT spending by user departments outside the control of the normal IT investment decision mechanisms and approved budgets | I1: Duplications or overlaps between various initiatives or other forms of wasted resources | J1: Insufficient IT resources, staff with inadequate skills or staff burnout / dissatisfaction | K1: IT-enabled changes or projects frequently failing to meet business needs and delivered late or over budget | L1: Reluctance by board members, executives or senior management to engage with IT, or a lack of committed business sponsorship for IT | M1: Complex IT operating model and/or unclear decision mechanisms for IT-related decisions | N1: Excessively high cost of IT | O1: Obstructed or failed implementation of new initiatives or innovations caused by the current IT architecture and systems | P1: Gap between business and technical knowledge, which leads to business users and information and/or technology specialists speaking different languages | Q1: Regular issues with data quality and integration of data across various sources | R1: High level of end-user computing, creating (among other problems) a lack of oversight and quality control over the applications that are being developed and put in operation | S1: Business departments implementing their own information solutions with little or no involvement of the enterprise IT department | T1: Ignorance of and/or noncompliance with privacy regulations | U1: Inability to exploit new technologies or innovate using I&T
A2: EDM01 | B2: 3 | C2: 3 | D2: 1 | E2: 1 | F2: 2 | G2: 2 | H2: 2 | I2: 1 | J2: 1 | K2: 1 | L2: 3 | M2: 3.5 | N2: 1 | O2: 1 | P2: 1 | Q2: 1 | R2: 2 | S2: 3 | T2: 1.5 | U2: 1 | W2: =SUM(B2:U2) -> 35
A3: EDM02 | B3: 2.5 | C3: 3 | D3: 1 | E3: 1 | F3: 1.5 | G3: 2.5 | H3: 2 | I3: 1.5 | J3: 0.5 | K3: 2.5 | L3: 1.5 | M3: 1 | N3: 3 | O3: 2 | P3: 1 | Q3: 1 | R3: 2 | S3: 2 | T3: 1 | U3: 2.5 | W3: =SUM(B3:U3) -> 35
A4: EDM03 | B4: 1 | C4: 1 | D4: 2 | E4: 1 | F4: 2 | G4: 2 | H4: 1 | I4: 1 | J4: 0 | K4: 0.5 | L4: 1 | M4: 0 | N4: 1 | O4: 1.5 | P4: 1 | Q4: 2 | R4: 1 | S4: 1 | T4: 2.5 | U4: 1 | W4: =SUM(B4:U4) -> 23.5
A5: EDM04 | B5: 1 | C5: 1 | D5: 1 | E5: 1 | F5: 1 | G5: 2 | H5: 3 | I5: 3.5 | J5: 3.5 | K5: 1 | L5: 1.5 | M5: 0 | N5: 4 | O5: 2 | P5: 1 | Q5: 1.5 | R5: 2 | S5: 2.5 | T5: 0 | U5: 1 | W5: =SUM(B5:U5) -> 33.5
A6: EDM05 | B6: 1 | C6: 1 | D6: 1 | E6: 1 | F6: 1.5 | G6: 2 | H6: 1 | I6: 1 | J6: 0 | K6: 1 | L6: 3 | M6: 1.5 | N6: 1.5 | O6: 0.5 | P6: 0 | Q6: 0.5 | R6: 1 | S6: 1 | T6: 1 | U6: 0 | W6: =SUM(B6:U6) -> 20.5
A7: APO01 | B7: 2 | C7: 1 | D7: 2 | E7: 1 | F7: 2 | G7: 2 | H7: 1 | I7: 1 | J7: 0 | K7: 0.5 | L7: 1.5 | M7: 4 | N7: 1 | O7: 2 | P7: 1 | Q7: 1 | R7: 1.5 | S7: 2 | T7: 0.5 | U7: 1 | W7: =SUM(B7:U7) -> 28
A8: APO02 | B8: 1.5 | C8: 1.5 | D8: 1.5 | E8: 1.5 | F8: 1 | G8: 1.5 | H8: 1 | I8: 1 | J8: 0 | K8: 1 | L8: 2.5 | M8: 0.5 | N8: 0.5 | O8: 1.5 | P8: 1.5 | Q8: 0.5 | R8: 2 | S8: 2 | T8: 0 | U8: 2.5 | W8: =SUM(B8:U8) -> 25
A9: APO03 | B9: 1 | C9: 1.5 | D9: 1 | E9: 2 | F9: 0.5 | G9: 1.5 | H9: 2 | I9: 1.5 | J9: 1 | K9: 3.5 | L9: 0.5 | M9: 0.5 | N9: 1 | O9: 4 | P9: 1 | Q9: 3.5 | R9: 2 | S9: 3 | T9: 0 | U9: 2 | W9: =SUM(B9:U9) -> 33
A10: APO04 | B10: 1 | C10: 1 | D10: 1 | E10: 1 | F10: 0.5 | G10: 0.5 | H10: 0.5 | I10: 0.5 | J10: 0 | K10: 0 | L10: 0.5 | M10: 1 | N10: 0.5 | O10: 2 | P10: 1 | Q10: 0 | R10: 0.5 | S10: 0.5 | T10: 0 | U10: 4 | W10: =SUM(B10:U10) -> 16
A11: APO05 | B11: 3 | C11: 3 | D11: 1 | E11: 1.5 | F11: 2 | G11: 2 | H11: 1.5 | I11: 3.5 | J11: 0.5 | K11: 2 | L11: 2 | M11: 1.5 | N11: 2 | O11: 1 | P11: 0.5 | Q11: 0 | R11: 2.5 | S11: 2.5 | T11: 0 | U11: 2 | W11: =SUM(B11:U11) -> 34
A12: APO06 | B12: 3.5 | C12: 2 | D12: 1 | E12: 1.5 | F12: 1.5 | G12: 2 | H12: 4 | I12: 3 | J12: 1 | K12: 2 | L12: 1 | M12: 1.5 | N12: 4 | O12: 0 | P12: 0 | Q12: 0 | R12: 1 | S12: 2 | T12: 0 | U12: 0 | W12: =SUM(B12:U12) -> 31
A13: APO07 | B13: 1.5 | C13: 1 | D13: 1 | E13: 1 | F13: 1 | G13: 1.5 | H13: 2 | I13: 2 | J13: 4 | K13: 1 | L13: 0 | M13: 0 | N13: 1 | O13: 0 | P13: 3 | Q13: 0 | R13: 0.5 | S13: 0.5 | T13: 1.5 | U13: 1 | W13: =SUM(B13:U13) -> 23.5
... A41: MEA04 | B41: 1 | C41: 1 | D41: 3 | E41: 1.5 | F41: 3 | G41: 4 | H41: 2 | I41: 1 | J41: 1 | K41: 0.5 | L41: 1 | M41: 1 | N41: 1.5 | O41: 0 | P41: 1 | Q41: 1 | R41: 1 | S41: 1 | T41: 2.5 | U41: 1 | W41: =SUM(B41:U41) -> 29

Sheet DF5
A1: Information & Technology Governance System Design Design Factor 5 Threat Landscape | G1: Information & Technology Governance System Design Design Factor 5 Threat Landscape
A3: Input Section—Importance of Threat Landscape | G3: Input Section—Importance of Threat Landscape
A6: Value | B6: Importance (100%) | D6: Baseline | H6: Page intentionally left blank
A7: High | B7: 0.1 | D7: 0.33
A8: Normal | B8: 0.9 | D8: 0.67
A10: Average
A11: Stdev
A12: Correction Factor | B12: 1
A26: Output Section—Resulting relative importance of each governance/management objective | G26: Output Section—Resulting relative importance of each governance/management objective
A28: Resulting Governance/ Management Objectives Importance
A29: Governance / Management Objective | B29: Score | C29: Baseline Score | D29: Relative Importance
A30: EDM01 | B30: {=MMULT(DF5map!B2:C41,'DF5'!B7:B8)} -> 1.2 | C30: {=MMULT(DF5map!B2:C41,'DF5'!D7:D8)} -> 1.66 | D30: =IFERROR(MROUND((100*B30/C30),5)-100,0) -> -30
A31: EDM02 | B31: 1 | C31: 1 | D31: =IFERROR(MROUND((100*B31/C31),5)-100,0) -> 0
A32: EDM03 | B32: 1.3 | C32: 1.99 | D32: =IFERROR(MROUND((100*B32/C32),5)-100,0) -> -35
A33: EDM04 | B33: 1 | C33: 1 | D33: =IFERROR(MROUND((100*B33/C33),5)-100,0) -> 0
A34: EDM05 | B34: 1.1 | C34: 1.33 | D34: =IFERROR(MROUND((100*B34/C34),5)-100,0) -> -15
A35: APO01 | B35: 1.2 | C35: 1.66 | D35: =IFERROR(MROUND((100*B35/C35),5)-100,0) -> -30
A36: APO02 | B36: 1 | C36: 1 | D36: =IFERROR(MROUND((100*B36/C36),5)-100,0) -> 0
A37: APO03 | B37: 1.2 | C37: 1.66 | D37: =IFERROR(MROUND((100*B37/C37),5)-100,0) -> -30
A38: APO04 | B38: 1 | C38: 1 | D38: =IFERROR(MROUND((100*B38/C38),5)-100,0) -> 0
A39: APO05 | B39: 1 | C39: 1 | D39: =IFERROR(MROUND((100*B39/C39),5)-100,0) -> 0
A40: APO06 | B40: 1 | C40: 1 | D40: =IFERROR(MROUND((100*B40/C40),5)-100,0) -> 0
A41: APO07 | B41: 1.1 | C41: 1.33 | D41: =IFERROR(MROUND((100*B41/C41),5)-100,0) -> -15
A42: APO08 | B42: 1 | C42: 1 | D42: =IFERROR(MROUND((100*B42/C42),5)-100,0) -> 0
... A69: MEA04 | B69: 1.2 | C69: 1.66 | D69: =IFERROR(MROUND((100*B69/C69),5)-100,0) -> -30

Sheet DF5map
A1: DF5 | B1: High | C1: Normal
A2: EDM01 | B2: 3 | C2: 1
A3: EDM02 | B3: 1 | C3: 1
A4: EDM03 | B4: 4 | C4: 1
A5: EDM04 | B5: 1 | C5: 1
A6: EDM05 | B6: 2 | C6: 1
A7: APO01 | B7: 3 | C7: 1
A8: APO02 | B8: 1 | C8: 1
A9: APO03 | B9: 3 | C9: 1
A10: APO04 | B10: 1 | C10: 1
A11: APO05 | B11: 1 | C11: 1
A12: APO06 | B12: 1 | C12: 1
A13: APO07 | B13: 2 | C13: 1
... A41: MEA04 | B41: 3 | C41: 1

Sheet DF6
A1: Information & Technology Governance System Design Design Factor 6 Compliance Requirements | G1: Information & Technology Governance System Design Design Factor 6 Compliance Requirements
A3: Input Section—Importance of Compliance Requirements | G3: Input Section—Importance of Compliance Requirements
A6: Value | B6: Importance (100%) | D6: Baseline | H6: Page intentionally left blank
A7: High | B7: 0.8 | D7: 0
A8: Normal | B8: 0.2 | D8: 1
A9: Low | B9: 0 | D9: 0
A11: Average
A12: Stdev
A24: Correction Factor | B24: 1
A26: Output Section—Resulting relative importance of each governance/management objective | G26: Output Section—Resulting relative importance of each governance/management objective
A28: Resulting Governance/ Management Objectives Importance
A29: Governance / Management Objective | B29: Score | C29: Baseline Score | D29: Relative Importance
A30: EDM01 | B30: {=MMULT(DF6map!B2:D41,'DF6'!B7:B9)} -> 2.8 | C30: {=MMULT(DF6map!B2:D41,'DF6'!D7:D9)} -> 2 | D30: =IFERROR(MROUND((100*B30/C30),5)-100,0) -> 40
A31: EDM02 | B31: 1 | C31: 1 | D31: =IFERROR(MROUND((100*B31/C31),5)-100,0) -> 0
A32: EDM03 | B32: 3.6 | C32: 2 | D32: =IFERROR(MROUND((100*B32/C32),5)-100,0) -> 80
A33: EDM04 | B33: 1 | C33: 1 | D33: =IFERROR(MROUND((100*B33/C33),5)-100,0) -> 0
A34: EDM05 | B34: 1.4 | C34: 1 | D34: =IFERROR(MROUND((100*B34/C34),5)-100,0) -> 40
A35: APO01 | B35: 1.9 | C35: 1.5 | D35: =IFERROR(MROUND((100*B35/C35),5)-100,0) -> 25
A36: APO02 | B36: 1 | C36: 1 | D36: =IFERROR(MROUND((100*B36/C36),5)-100,0) -> 0
A37: APO03 | B37: 1 | C37: 1 | D37: =IFERROR(MROUND((100*B37/C37),5)-100,0) -> 0
A38: APO04 | B38: 1 | C38: 1 | D38: =IFERROR(MROUND((100*B38/C38),5)-100,0) -> 0
A39: APO05 | B39: 1 | C39: 1 | D39: =IFERROR(MROUND((100*B39/C39),5)-100,0) -> 0
A40: APO06 | B40: 1 | C40: 1 | D40: =IFERROR(MROUND((100*B40/C40),5)-100,0) -> 0
A41: APO07 | B41: 1 | C41: 1 | D41: =IFERROR(MROUND((100*B41/C41),5)-100,0) -> 0
A42: APO08 | B42: 1 | C42: 1 | D42: =IFERROR(MROUND((100*B42/C42),5)-100,0) -> 0
... A69: MEA04 | B69: 3.2 | C69: 2 | D69: =IFERROR(MROUND((100*B69/C69),5)-100,0) -> 60

Sheet DF6map
A1: DF6 | B1: High | C1: Normal | D1: Low
A2: EDM01 | B2: 3 | C2: 2 | D2: 1
A3: EDM02 | B3: 1 | C3: 1 | D3: 1
A4: EDM03 | B4: 4 | C4: 2 | D4: 1
A5: EDM04 | B5: 1 | C5: 1 | D5: 1
A6: EDM05 | B6: 1.5 | C6: 1 | D6: 1
A7: APO01 | B7: 2 | C7: 1.5 | D7: 1
A8: APO02 | B8: 1 | C8: 1 | D8: 1
A9: APO03 | B9: 1 | C9: 1 | D9: 1
A10: APO04 | B10: 1 | C10: 1 | D10: 1
A11: APO05 | B11: 1 | C11: 1 | D11: 1
A12: APO06 | B12: 1 | C12: 1 | D12: 1
